[2022-02-24 23:52:31,434] {taskinstance.py:1037} INFO - Dependencies all met for <TaskInstance: daily_fuel_data_ingestion.format_to_parquet_task manual__2022-02-24T22:55:20.271881+00:00 [queued]>
[2022-02-24 23:52:31,449] {taskinstance.py:1037} INFO - Dependencies all met for <TaskInstance: daily_fuel_data_ingestion.format_to_parquet_task manual__2022-02-24T22:55:20.271881+00:00 [queued]>
[2022-02-24 23:52:31,450] {taskinstance.py:1243} INFO - 
--------------------------------------------------------------------------------
[2022-02-24 23:52:31,450] {taskinstance.py:1244} INFO - Starting attempt 7 of 7
[2022-02-24 23:52:31,450] {taskinstance.py:1245} INFO - 
--------------------------------------------------------------------------------
[2022-02-24 23:52:31,471] {taskinstance.py:1264} INFO - Executing <Task(PythonOperator): format_to_parquet_task> on 2022-02-24 22:55:20.271881+00:00
[2022-02-24 23:52:31,480] {standard_task_runner.py:52} INFO - Started process 2847 to run task
[2022-02-24 23:52:31,487] {standard_task_runner.py:76} INFO - Running: ['***', 'tasks', 'run', 'daily_fuel_data_ingestion', 'format_to_parquet_task', 'manual__2022-02-24T22:55:20.271881+00:00', '--job-id', '33', '--raw', '--subdir', 'DAGS_FOLDER/ingest_daily_fuel_data_dag.py', '--cfg-path', '/tmp/tmpymbchlqy', '--error-file', '/tmp/tmpn5szd_0f']
[2022-02-24 23:52:31,489] {standard_task_runner.py:77} INFO - Job 33: Subtask format_to_parquet_task
[2022-02-24 23:52:31,567] {logging_mixin.py:109} INFO - Running <TaskInstance: daily_fuel_data_ingestion.format_to_parquet_task manual__2022-02-24T22:55:20.271881+00:00 [running]> on host 036a2a858d52
[2022-02-24 23:52:31,623] {warnings.py:110} WARNING - /home/***/.local/lib/python3.7/site-packages/***/utils/context.py:156: AirflowContextDeprecationWarning: Accessing 'execution_date' from the template is deprecated and will be removed in a future version. Please use 'data_interval_start' or 'logical_date' instead.
  warnings.warn(_create_deprecation_warning(key, self._deprecation_replacements[key]))

[2022-02-24 23:52:31,653] {taskinstance.py:1431} INFO - Exporting the following env vars:
AIRFLOW_CTX_DAG_OWNER=***
AIRFLOW_CTX_DAG_ID=daily_fuel_data_ingestion
AIRFLOW_CTX_TASK_ID=format_to_parquet_task
AIRFLOW_CTX_EXECUTION_DATE=2022-02-24T22:55:20.271881+00:00
AIRFLOW_CTX_DAG_RUN_ID=manual__2022-02-24T22:55:20.271881+00:00
[2022-02-24 23:52:31,654] {taskinstance.py:1718} ERROR - Task failed with exception
Traceback (most recent call last):
  File "/home/airflow/.local/lib/python3.7/site-packages/airflow/models/taskinstance.py", line 1334, in _run_raw_task
    self._execute_task_with_callbacks(context)
  File "/home/airflow/.local/lib/python3.7/site-packages/airflow/models/taskinstance.py", line 1460, in _execute_task_with_callbacks
    result = self._execute_task(context, self.task)
  File "/home/airflow/.local/lib/python3.7/site-packages/airflow/models/taskinstance.py", line 1516, in _execute_task
    result = execute_callable(context=context)
  File "/home/airflow/.local/lib/python3.7/site-packages/airflow/operators/python.py", line 174, in execute
    return_value = self.execute_callable()
  File "/home/airflow/.local/lib/python3.7/site-packages/airflow/operators/python.py", line 188, in execute_callable
    return self.python_callable(*self.op_args, **self.op_kwargs)
  File "/opt/airflow/dags/ingest_daily_fuel_data_dag.py", line 88, in format_to_parquet
    table = pv.read_csv(src_file)
  File "pyarrow/_csv.pyx", line 881, in pyarrow._csv.read_csv
  File "pyarrow/_csv.pyx", line 774, in pyarrow._csv._get_reader
  File "pyarrow/io.pxi", line 1631, in pyarrow.lib.get_input_stream
  File "pyarrow/io.pxi", line 1602, in pyarrow.lib.get_native_file
  File "pyarrow/io.pxi", line 896, in pyarrow.lib.OSFile.__cinit__
  File "pyarrow/io.pxi", line 906, in pyarrow.lib.OSFile._open_readable
  File "pyarrow/error.pxi", line 143, in pyarrow.lib.pyarrow_internal_check_status
  File "pyarrow/error.pxi", line 112, in pyarrow.lib.check_status
FileNotFoundError: [Errno 2] Failed to open local file '/opt/airflow/daily_fuel_data_24-Feb-2022.csv'. Detail: [errno 2] No such file or directory
[2022-02-24 23:52:31,674] {taskinstance.py:1282} INFO - Marking task as FAILED. dag_id=daily_fuel_data_ingestion, task_id=format_to_parquet_task, execution_date=20220224T225520, start_date=20220224T235231, end_date=20220224T235231
[2022-02-24 23:52:31,694] {standard_task_runner.py:92} ERROR - Failed to execute job 33 for task format_to_parquet_task
Traceback (most recent call last):
  File "/home/airflow/.local/lib/python3.7/site-packages/airflow/task/task_runner/standard_task_runner.py", line 85, in _start_by_fork
    args.func(args, dag=self.dag)
  File "/home/airflow/.local/lib/python3.7/site-packages/airflow/cli/cli_parser.py", line 48, in command
    return func(*args, **kwargs)
  File "/home/airflow/.local/lib/python3.7/site-packages/airflow/utils/cli.py", line 92, in wrapper
    return f(*args, **kwargs)
  File "/home/airflow/.local/lib/python3.7/site-packages/airflow/cli/commands/task_command.py", line 298, in task_run
    _run_task_by_selected_method(args, dag, ti)
  File "/home/airflow/.local/lib/python3.7/site-packages/airflow/cli/commands/task_command.py", line 107, in _run_task_by_selected_method
    _run_raw_task(args, ti)
  File "/home/airflow/.local/lib/python3.7/site-packages/airflow/cli/commands/task_command.py", line 184, in _run_raw_task
    error_file=args.error_file,
  File "/home/airflow/.local/lib/python3.7/site-packages/airflow/utils/session.py", line 70, in wrapper
    return func(*args, session=session, **kwargs)
  File "/home/airflow/.local/lib/python3.7/site-packages/airflow/models/taskinstance.py", line 1334, in _run_raw_task
    self._execute_task_with_callbacks(context)
  File "/home/airflow/.local/lib/python3.7/site-packages/airflow/models/taskinstance.py", line 1460, in _execute_task_with_callbacks
    result = self._execute_task(context, self.task)
  File "/home/airflow/.local/lib/python3.7/site-packages/airflow/models/taskinstance.py", line 1516, in _execute_task
    result = execute_callable(context=context)
  File "/home/airflow/.local/lib/python3.7/site-packages/airflow/operators/python.py", line 174, in execute
    return_value = self.execute_callable()
  File "/home/airflow/.local/lib/python3.7/site-packages/airflow/operators/python.py", line 188, in execute_callable
    return self.python_callable(*self.op_args, **self.op_kwargs)
  File "/opt/airflow/dags/ingest_daily_fuel_data_dag.py", line 88, in format_to_parquet
    table = pv.read_csv(src_file)
  File "pyarrow/_csv.pyx", line 881, in pyarrow._csv.read_csv
  File "pyarrow/_csv.pyx", line 774, in pyarrow._csv._get_reader
  File "pyarrow/io.pxi", line 1631, in pyarrow.lib.get_input_stream
  File "pyarrow/io.pxi", line 1602, in pyarrow.lib.get_native_file
  File "pyarrow/io.pxi", line 896, in pyarrow.lib.OSFile.__cinit__
  File "pyarrow/io.pxi", line 906, in pyarrow.lib.OSFile._open_readable
  File "pyarrow/error.pxi", line 143, in pyarrow.lib.pyarrow_internal_check_status
  File "pyarrow/error.pxi", line 112, in pyarrow.lib.check_status
FileNotFoundError: [Errno 2] Failed to open local file '/opt/airflow/daily_fuel_data_24-Feb-2022.csv'. Detail: [errno 2] No such file or directory
[2022-02-24 23:52:31,741] {local_task_job.py:154} INFO - Task exited with return code 1
[2022-02-24 23:52:31,800] {local_task_job.py:264} INFO - 0 downstream tasks scheduled from follow-on schedule check
